Exception in user code:
------------------------------------------------------------
Setting up a new session...
Traceback (most recent call last):
  File "/Users/vincentvanengers/Pvenvs/it_project/lib/python3.8/site-packages/urllib3/connection.py", line 174, in _new_conn
    conn = connection.create_connection(
  File "/Users/vincentvanengers/Pvenvs/it_project/lib/python3.8/site-packages/urllib3/util/connection.py", line 95, in create_connection
    raise err
  File "/Users/vincentvanengers/Pvenvs/it_project/lib/python3.8/site-packages/urllib3/util/connection.py", line 85, in create_connection
    sock.connect(sa)
ConnectionRefusedError: [Errno 61] Connection refused
During handling of the above exception, another exception occurred:
Traceback (most recent call last):
  File "/Users/vincentvanengers/Pvenvs/it_project/lib/python3.8/site-packages/urllib3/connectionpool.py", line 703, in urlopen
    httplib_response = self._make_request(
  File "/Users/vincentvanengers/Pvenvs/it_project/lib/python3.8/site-packages/urllib3/connectionpool.py", line 398, in _make_request
    conn.request(method, url, **httplib_request_kw)
  File "/Users/vincentvanengers/Pvenvs/it_project/lib/python3.8/site-packages/urllib3/connection.py", line 239, in request
    super(HTTPConnection, self).request(method, url, body=body, headers=headers)
  File "/Library/Frameworks/Python.framework/Versions/3.8/lib/python3.8/http/client.py", line 1252, in request
    self._send_request(method, url, body, headers, encode_chunked)
  File "/Library/Frameworks/Python.framework/Versions/3.8/lib/python3.8/http/client.py", line 1298, in _send_request
    self.endheaders(body, encode_chunked=encode_chunked)
  File "/Library/Frameworks/Python.framework/Versions/3.8/lib/python3.8/http/client.py", line 1247, in endheaders
    self._send_output(message_body, encode_chunked=encode_chunked)
  File "/Library/Frameworks/Python.framework/Versions/3.8/lib/python3.8/http/client.py", line 1007, in _send_output
    self.send(msg)
  File "/Library/Frameworks/Python.framework/Versions/3.8/lib/python3.8/http/client.py", line 947, in send
    self.connect()
  File "/Users/vincentvanengers/Pvenvs/it_project/lib/python3.8/site-packages/urllib3/connection.py", line 205, in connect
    conn = self._new_conn()
  File "/Users/vincentvanengers/Pvenvs/it_project/lib/python3.8/site-packages/urllib3/connection.py", line 186, in _new_conn
    raise NewConnectionError(
urllib3.exceptions.NewConnectionError: <urllib3.connection.HTTPConnection object at 0x7fc6bf42f220>: Failed to establish a new connection: [Errno 61] Connection refused
During handling of the above exception, another exception occurred:
Traceback (most recent call last):
  File "/Users/vincentvanengers/Pvenvs/it_project/lib/python3.8/site-packages/requests/adapters.py", line 440, in send
    resp = conn.urlopen(
  File "/Users/vincentvanengers/Pvenvs/it_project/lib/python3.8/site-packages/urllib3/connectionpool.py", line 785, in urlopen
    retries = retries.increment(
  File "/Users/vincentvanengers/Pvenvs/it_project/lib/python3.8/site-packages/urllib3/util/retry.py", line 592, in increment
    raise MaxRetryError(_pool, url, error or ResponseError(cause))
urllib3.exceptions.MaxRetryError: HTTPConnectionPool(host='localhost', port=8097): Max retries exceeded with url: /env/MLP-lambda40-in1024-out10-h400x2-dropout_in0.2_hidden0.5 (Caused by NewConnectionError('<urllib3.connection.HTTPConnection object at 0x7fc6bf42f220>: Failed to establish a new connection: [Errno 61] Connection refused'))
During handling of the above exception, another exception occurred:
Traceback (most recent call last):
  File "/Users/vincentvanengers/Pvenvs/it_project/lib/python3.8/site-packages/visdom/__init__.py", line 708, in _send
    return self._handle_post(
  File "/Users/vincentvanengers/Pvenvs/it_project/lib/python3.8/site-packages/visdom/__init__.py", line 677, in _handle_post
    r = self.session.post(url, data=data)
  File "/Users/vincentvanengers/Pvenvs/it_project/lib/python3.8/site-packages/requests/sessions.py", line 577, in post
    return self.request('POST', url, data=data, json=json, **kwargs)
  File "/Users/vincentvanengers/Pvenvs/it_project/lib/python3.8/site-packages/requests/sessions.py", line 529, in request
    resp = self.send(prep, **send_kwargs)
  File "/Users/vincentvanengers/Pvenvs/it_project/lib/python3.8/site-packages/requests/sessions.py", line 645, in send
    r = adapter.send(request, **kwargs)
  File "/Users/vincentvanengers/Pvenvs/it_project/lib/python3.8/site-packages/requests/adapters.py", line 519, in send
    raise ConnectionError(e, request=request)
requests.exceptions.ConnectionError: HTTPConnectionPool(host='localhost', port=8097): Max retries exceeded with url: /env/MLP-lambda40-in1024-out10-h400x2-dropout_in0.2_hidden0.5 (Caused by NewConnectionError('<urllib3.connection.HTTPConnection object at 0x7fc6bf42f220>: Failed to establish a new connection: [Errno 61] Connection refused'))
[Errno 61] Connection refused
on_close() takes 1 positional argument but 3 were given

















469it [00:35, 13.18it/s]















469it [00:31, 14.75it/s]














469it [00:30, 15.28it/s]






219it [00:14, 15.38it/s]
Traceback (most recent call last):
  File "/Users/vincentvanengers/Documents/ut/q3/it/Overcoming-Catastrophic-Forgetting-in-Sparse-Evolutionairy-Training/main.py", line 73, in <module>
    train(
  File "/Users/vincentvanengers/Documents/ut/q3/it/Overcoming-Catastrophic-Forgetting-in-Sparse-Evolutionairy-Training/train.py", line 68, in train
    loss.backward()
  File "/Users/vincentvanengers/Pvenvs/it_project/lib/python3.8/site-packages/torch/_tensor.py", line 363, in backward
    torch.autograd.backward(self, gradient, retain_graph, create_graph, inputs=inputs)
  File "/Users/vincentvanengers/Pvenvs/it_project/lib/python3.8/site-packages/torch/autograd/__init__.py", line 173, in backward
    Variable._execution_engine.run_backward(  # Calls into the C++ engine to run the backward pass
KeyboardInterrupt